Traceback (most recent call last):
  File "download_stock_data.py", line 30, in <module>
    data = pd.read_csv(url)
  File "/home/pi/.local/lib/python2.7/site-packages/pandas/io/parsers.py", line 702, in parser_f
    return _read(filepath_or_buffer, kwds)
  File "/home/pi/.local/lib/python2.7/site-packages/pandas/io/parsers.py", line 413, in _read
    filepath_or_buffer, encoding, compression)
  File "/home/pi/.local/lib/python2.7/site-packages/pandas/io/common.py", line 202, in get_filepath_or_buffer
    req = _urlopen(filepath_or_buffer)
  File "/usr/lib/python2.7/urllib2.py", line 154, in urlopen
    return opener.open(url, data, timeout)
  File "/usr/lib/python2.7/urllib2.py", line 429, in open
    response = self._open(req, data)
  File "/usr/lib/python2.7/urllib2.py", line 447, in _open
    '_open', req)
  File "/usr/lib/python2.7/urllib2.py", line 407, in _call_chain
    result = func(*args)
  File "/usr/lib/python2.7/urllib2.py", line 1241, in https_open
    context=self._context)
  File "/usr/lib/python2.7/urllib2.py", line 1201, in do_open
    r = h.getresponse(buffering=True)
  File "/usr/lib/python2.7/httplib.py", line 1121, in getresponse
    response.begin()
  File "/usr/lib/python2.7/httplib.py", line 438, in begin
    version, status, reason = self._read_status()
  File "/usr/lib/python2.7/httplib.py", line 402, in _read_status
    raise BadStatusLine("No status line received - the server has closed the connection")
httplib.BadStatusLine: No status line received - the server has closed the connection
